Workbook
Name Slicer_Country: #N/A
Name Slicer_Region: #N/A

Sheet DATA
A1: Job ID | B1: Job Title | C1: Country | D1: Region | E1: Work Type | F1: Experience | G1: Salary USD | H1: Lookup Region | I1: Salary Level
A2: J001 | B2: Data Analyst | C2: Kenya | D2: Africa | E2: On-site | F2: Entry | G2: 12000 | H2: =_xlfn.XLOOKUP(jobs[[#This Row],[Country]],LOOKUP!$A$2:$A$8,LOOKUP!$B$2:$B$8,"Not Found") -> Africa | I2: =IF(jobs[[#This Row],[Salary USD]]>=70000,"High",IF(jobs[[#This Row],[Salary USD]]>=30000,"Medium","Low")) -> Low
A3: J002 | B3: Data Analyst | C3: United States | D3: North America | E3: Remote | F3: Mid | G3: 85000 | H3: =_xlfn.XLOOKUP(jobs[[#This Row],[Country]],LOOKUP!$A$2:$A$8,LOOKUP!$B$2:$B$8,"Not Found") -> North America | I3: =IF(jobs[[#This Row],[Salary USD]]>=70000,"High",IF(jobs[[#This Row],[Salary USD]]>=30000,"Medium","Low")) -> High
A4: J003 | B4: Software Engineer | C4: Germany | D4: Europe | E4: Hybrid | F4: Mid | G4: 72000 | H4: =_xlfn.XLOOKUP(jobs[[#This Row],[Country]],LOOKUP!$A$2:$A$8,LOOKUP!$B$2:$B$8,"Not Found") -> Europe | I4: =IF(jobs[[#This Row],[Salary USD]]>=70000,"High",IF(jobs[[#This Row],[Salary USD]]>=30000,"Medium","Low")) -> High
A5: J004 | B5: IT Support Specialist | C5: Kenya | D5: Africa | E5: On-site | F5: Entry | G5: 10000 | H5: =_xlfn.XLOOKUP(jobs[[#This Row],[Country]],LOOKUP!$A$2:$A$8,LOOKUP!$B$2:$B$8,"Not Found") -> Africa | I5: =IF(jobs[[#This Row],[Salary USD]]>=70000,"High",IF(jobs[[#This Row],[Salary USD]]>=30000,"Medium","Low")) -> Low
A6: J005 | B6: Data Analyst | C6: United Kingdom | D6: Europe | E6: Hybrid | F6: Senior | G6: 68000 | H6: =_xlfn.XLOOKUP(jobs[[#This Row],[Country]],LOOKUP!$A$2:$A$8,LOOKUP!$B$2:$B$8,"Not Found") -> Europe | I6: =IF(jobs[[#This Row],[Salary USD]]>=70000,"High",IF(jobs[[#This Row],[Salary USD]]>=30000,"Medium","Low")) -> Medium
A7: J006 | B7: Software Engineer | C7: India | D7: Asia | E7: Remote | F7: Mid | G7: 42000 | H7: =_xlfn.XLOOKUP(jobs[[#This Row],[Country]],LOOKUP!$A$2:$A$8,LOOKUP!$B$2:$B$8,"Not Found") -> Asia | I7: =IF(jobs[[#This Row],[Salary USD]]>=70000,"High",IF(jobs[[#This Row],[Salary USD]]>=30000,"Medium","Low")) -> Medium
A8: J007 | B8: Cybersecurity Analyst | C8: United States | D8: North America | E8: Hybrid | F8: Senior | G8: 105000 | H8: =_xlfn.XLOOKUP(jobs[[#This Row],[Country]],LOOKUP!$A$2:$A$8,LOOKUP!$B$2:$B$8,"Not Found") -> North America | I8: =IF(jobs[[#This Row],[Salary USD]]>=70000,"High",IF(jobs[[#This Row],[Salary USD]]>=30000,"Medium","Low")) -> High
A9: J008 | B9: IT Support Specialist | C9: Germany | D9: Europe | E9: On-site | F9: Entry | G9: 39000 | H9: =_xlfn.XLOOKUP(jobs[[#This Row],[Country]],LOOKUP!$A$2:$A$8,LOOKUP!$B$2:$B$8,"Not Found") -> Europe | I9: =IF(jobs[[#This Row],[Salary USD]]>=70000,"High",IF(jobs[[#This Row],[Salary USD]]>=30000,"Medium","Low")) -> Medium
A10: J009 | B10: Data Analyst | C10: South Africa | D10: Africa | E10: Remote | F10: Mid | G10: 30000 | H10: =_xlfn.XLOOKUP(jobs[[#This Row],[Country]],LOOKUP!$A$2:$A$8,LOOKUP!$B$2:$B$8,"Not Found") -> Africa | I10: =IF(jobs[[#This Row],[Salary USD]]>=70000,"High",IF(jobs[[#This Row],[Salary USD]]>=30000,"Medium","Low")) -> Medium
A11: J010 | B11: Software Engineer | C11: Canada | D11: North America | E11: Hybrid | F11: Senior | G11: 92000 | H11: =_xlfn.XLOOKUP(jobs[[#This Row],[Country]],LOOKUP!$A$2:$A$8,LOOKUP!$B$2:$B$8,"Not Found") -> North America | I11: =IF(jobs[[#This Row],[Salary USD]]>=70000,"High",IF(jobs[[#This Row],[Salary USD]]>=30000,"Medium","Low")) -> High
A12: J011 | B12: Data Analyst | C12: India | D12: Asia | E12: On-site | F12: Entry | G12: 18000 | H12: =_xlfn.XLOOKUP(jobs[[#This Row],[Country]],LOOKUP!$A$2:$A$8,LOOKUP!$B$2:$B$8,"Not Found") -> Asia | I12: =IF(jobs[[#This Row],[Salary USD]]>=70000,"High",IF(jobs[[#This Row],[Salary USD]]>=30000,"Medium","Low")) -> Low
A13: J012 | B13: Cybersecurity Analyst | C13: United Kingdom | D13: Europe | E13: Remote | F13: Senior | G13: 76000 | H13: =_xlfn.XLOOKUP(jobs[[#This Row],[Country]],LOOKUP!$A$2:$A$8,LOOKUP!$B$2:$B$8,"Not Found") -> Europe | I13: =IF(jobs[[#This Row],[Salary USD]]>=70000,"High",IF(jobs[[#This Row],[Salary USD]]>=30000,"Medium","Low")) -> High
... A16: J015 | B16: Data Analyst | C16: Canada | D16: North America | E16: Remote | F16: Mid | G16: 65000 | H16: =_xlfn.XLOOKUP(jobs[[#This Row],[Country]],LOOKUP!$A$2:$A$8,LOOKUP!$B$2:$B$8,"Not Found") -> North America | I16: =IF(jobs[[#This Row],[Salary USD]]>=70000,"High",IF(jobs[[#This Row],[Salary USD]]>=30000,"Medium","Low")) -> Medium

Sheet LOOKUP
A1: Country | B1: Region
A2: {=_xlfn.UNIQUE(jobs[Country])} -> Kenya | B2: Africa
A3: United States | B3: North America
A4: Germany | B4: Europe
A5: United Kingdom | B5: Europe
A6: India | B6: Asia
A7: South Africa | B7: Africa
A8: Canada | B8: North America

Sheet PIVOT
A3: Row Labels | B3: Average of Salary USD
A4: Africa | B4: 20000
A5: Asia | B5: 24666.667
A6: Europe | B6: 63750
A7: North America | B7: 86750
A8: Grand Total | B8: 50400
A11: Row Labels | B11: Count of Job ID
A12: Data Analyst | B12: 6
A13: Software Engineer | B13: 4
A14: IT Support Specialist | B14: 3
A15: Cybersecurity Analyst | B15: 2
A16: Grand Total | B16: 15
A19: Count of Job ID | B19: Column Labels
A20: Row Labels | B20: High | C20: Low | D20: Medium | E20: Grand Total
A21: Africa | C21: 3 | D21: 1 | E21: 4
A22: Asia | C22: 2 | D22: 1 | E22: 3
A23: Europe | B23: 2 | D23: 2 | E23: 4
A24: North America | B24: 3 | D24: 1 | E24: 4
A25: Grand Total | B25: 5 | C25: 5 | D25: 5 | E25: 15
A28: Row Labels | B28: Count of Job ID
A29: Hybrid | B29: 5
A30: On-site | B30: 5
A31: Remote | B31: 5
A32: Grand Total | B32: 15
A35: Row Labels | B35: Count of Job ID
A36: Africa | B36: 4
A37: Asia | B37: 3
A38: Europe | B38: 4
A39: North America | B39: 4
A40: Grand Total | B40: 15
A43: Row Labels | B43: Average of Salary USD
A44: United States | B44: 95000
A45: Canada | B45: 78500
A46: United Kingdom | B46: 72000
A47: Germany | B47: 55500
A48: South Africa | B48: 30000
A49: India | B49: 24666.667
A50: Kenya | B50: 16666.667
A51: Grand Total | B51: 50400
A54: Count of Job ID | B54: Column Labels
...

Sheet DASHBOARD
B2: GLOBAL TECH JOBS DASHBOARD
B4: TOTAL JOBS | H4: AVERAGE SALARY | J4: TOP ROLE JOB | Q4: REMOTE JOBS
B5: =A62 -> 15 | H5: =A67 -> 50400 | J5: =_xlfn.LET( _xlpm.da,IFERROR(GETPIVOTDATA("Job ID",$A$76,"Job Title","Data Analyst"),0), _xlpm.se,IFERROR(GETPIVOTDATA("Job ID",$A$76,"Job Title","Software Engineer"),0), _xlpm.it,IFERROR(GETPIVOTDATA("Job ID",$A$76,"Job Title","IT Support Specialist"),0), _xlpm.cs,IFERROR(GETPIVOTDATA("Job ID",$A$76,"Job Title","Cybersecurity Analyst"),0), _xlpm.top,MAX(_xlpm.da,_xlpm.se,_xlpm.it,_xlpm.cs), _xlfn.TEXTJOIN(" / ",TRUE, IF(_xlpm.da=_xlpm.top,"Data Analyst",""), IF(_xlpm.se=_xlpm.top,"Software Engineer",""), IF(_xlpm.it=_xlpm.top,"IT Support Specialist",""), IF(_xlpm.cs=_xlpm.top,"Cybersecurity Analyst","")) ) -> Data Analyst | Q5: =GETPIVOTDATA("Job ID",$A$70) -> 5
L7: KEY INSIGHTS
L8: ="The most common role is "&J5&", accounting for "&TEXT(1/B5,"0.0%")&" of the selected jobs." -> The most common role is Data Analyst, accounting for 6.7% of the selected jobs.
L9: ="The average salary for the selected data is "&TEXT(H5,"$#,##0") -> The average salary for the selected data is $50,400
L10: =Q5&" of "&B5&" selected jobs are remote ("&TEXT(Q5/B5,"0.0%")&")." -> 5 of 15 selected jobs are remote (33.3%).
L11: ="The selected data contains "&B5&" jobs across different technology roles and "&Q5&" are remote." -> The selected data contains 15 jobs across different technology roles and 5 are remote.
A60: Count of Job ID
A61: 15
A62: =GETPIVOTDATA("Job ID",$A$60) -> 15
A65: Average of Salary USD
A66: 50400
A67: =GETPIVOTDATA("Salary USD",$A$65) -> 50400
A68: Work Type | B68: Remote
A70: Count of Job ID
A71: 5
A72: =GETPIVOTDATA("Job ID",$A$68) -> 5
A75: Row Labels | B75: Count of Job ID
A76: Data Analyst | B76: 6
A77: Software Engineer | B77: 4
A78: IT Support Specialist | B78: 3
A79: Cybersecurity Analyst | B79: 2
A80: Grand Total | B80: 15
